<?xml version="1.0" ?>
<!-- =================================================================================== -->
<!-- |    This document was autogenerated by xacro from turtle_bot.urdf.xacro          | -->
<!-- |    EDITING THIS FILE BY HAND IS NOT RECOMMENDED                                 | -->
<!-- =================================================================================== -->
<robot name="turtle-bot">
  <material name="green">
    <color rgba="0 1 0 1"/>
  </material>
  <material name="white">
    <color rgba="1 1 1 1"/>
  </material>
  <material name="gray">
    <color rgba="0.2 0.2 0.2 1"/>
  </material>
  <material name="orange">
    <color rgba="1 0.3 0.1 1"/>
  </material>
  <material name="blue">
    <color rgba="0.2 0.2 1 1"/>
  </material>
  <link name="base_link">
    <visual>
      <geometry>
        <box size="2.0 2.0 2.0"/>
      </geometry>
      <material name="green"/>
    </visual>
    <collision>
      <geometry>
        <box size="2.0 2.0 2.0"/>
      </geometry>
    </collision>
  </link>
  <link name="fixed_link">
    <visual>
      <origin rpy="0 0 0" xyz="0 0 0"/>
      <geometry>
        <cylinder length="2.0" radius="0.2"/>
      </geometry>
      <material name="white"/>
    </visual>
    <collision>
      <origin rpy="0 0 0" xyz="0 0 0"/>
      <geometry>
        <cylinder length="2.0" radius="0.2"/>
      </geometry>
    </collision>
  </link>
  <link name="platform_link">
    <visual>
      <origin rpy="0 0 0" xyz="0 0 0.1"/>
      <geometry>
        <cylinder length="0.2" radius="2"/>
      </geometry>
      <material name="blue"/>
    </visual>
    <collision>
      <origin rpy="0 0 0" xyz="0 0 0"/>
      <geometry>
        <cylinder length="0.2" radius="2"/>
      </geometry>
    </collision>
  </link>
  <link name="stem_link">
    <visual>
      <origin rpy="0 0 0" xyz="0 0 -0.5"/>
      <geometry>
        <cylinder length="1.0" radius="0.5"/>
      </geometry>
      <material name="orange"/>
    </visual>
    <collision>
      <origin rpy="0 0 0" xyz="0 0 0"/>
      <geometry>
        <cylinder length="-1.0" radius="0.65"/>
      </geometry>
    </collision>
  </link>
  <link name="wheel_link">
    <visual>
      <origin rpy="0 1.5707963267948966 0" xyz="0 0 0"/>
      <geometry>
        <cylinder length="0.5" radius="2"/>
      </geometry>
      <material name="gray"/>
    </visual>
    <collision>
      <origin rpy="0 1.5707963267948966 0" xyz="0 0 0"/>
      <geometry>
        <cylinder length="0.5" radius="2"/>
      </geometry>
    </collision>
  </link>
  <joint name="fixed_joint" type="fixed">
    <origin rpy="0 0 0" xyz="0 0 2.0"/>
    <parent link="base_link"/>
    <child link="fixed_link"/>
  </joint>
  <joint name="platform_joint" type="revolute">
    <origin rpy="0 0 0" xyz="0 0 1.0"/>
    <parent link="fixed_link"/>
    <child link="platform_link"/>
    <axis xyz="1 0 0"/>
    <limit effort="100" lower="0" upper="6.283185307179586" velocity="100"/>
  </joint>
  <joint name="stem_joint" type="revolute">
    <origin rpy="0 0 0" xyz="0 0 -1.0"/>
    <parent link="base_link"/>
    <child link="stem_link"/>
    <axis xyz="0 0 1"/>
    <limit effort="100" lower="0" upper="6.283185307179586" velocity="100"/>
  </joint>
  <joint name="wheel_joint" type="revolute">
    <origin rpy="0 0 0" xyz="0 0 -3.0"/>
    <parent link="stem_link"/>
    <child link="wheel_link"/>
    <axis xyz="1 0 0"/>
    <limit effort="100" lower="0" upper="6.283185307179586" velocity="100"/>
  </joint>
</robot>
